<mujoco model="ur10_reach_comparison">
    <compiler angle="radian" meshdir="ur10e/assets" autolimits="true"/>
    
    <option gravity="0 0 -9.81" integrator="implicit"/>
    
    <visual>
        <global offwidth="1024" offheight="768"/>
    </visual>
    
    <asset>
        <texture type="skybox" builtin="gradient" rgb1="0.3 0.5 0.7" rgb2="0 0 0" width="512" height="512"/>
        <texture name="texplane" type="2d" builtin="checker" rgb1="0.2 0.3 0.4" rgb2="0.1 0.2 0.3" width="512" height="512" mark="cross" markrgb=".8 .8 .8"/>
        <material name="matplane" reflectance="0.3" texture="texplane" texrepeat="1 1" texuniform="true"/>
        <material name="wall" rgba="0.9 0.9 0.9 1" reflectance="0.2"/>
        
        <!-- UR10e materials -->
        <material name="black" rgba="0.033 0.033 0.033 1" specular="0.5" shininess="0.25"/>
        <material name="jointgray" rgba="0.278 0.278 0.278 1" specular="0.5" shininess="0.25"/>
        <material name="linkgray" rgba="0.82 0.82 0.82 1" specular="0.5" shininess="0.25"/>
        <material name="urblue" rgba="0.49 0.678 0.8 1" specular="0.5" shininess="0.25"/>
        <material name="flatmount" rgba="0.6 0.3 0.3 1"/>
        <material name="perpmount" rgba="0.3 0.3 0.6 1"/>

        <!-- UR10e meshes -->
        <mesh file="base_0.obj"/>
        <mesh file="base_1.obj"/>
        <mesh file="shoulder_0.obj"/>
        <mesh file="shoulder_1.obj"/>
        <mesh file="shoulder_2.obj"/>
        <mesh file="upperarm_0.obj"/>
        <mesh file="upperarm_1.obj"/>
        <mesh file="upperarm_2.obj"/>
        <mesh file="upperarm_3.obj"/>
        <mesh file="forearm_0.obj"/>
        <mesh file="forearm_1.obj"/>
        <mesh file="forearm_2.obj"/>
        <mesh file="forearm_3.obj"/>
        <mesh file="wrist1_0.obj"/>
        <mesh file="wrist1_1.obj"/>
        <mesh file="wrist1_2.obj"/>
        <mesh file="wrist2_0.obj"/>
        <mesh file="wrist2_1.obj"/>
        <mesh file="wrist2_2.obj"/>
        <mesh file="wrist3.obj"/>
    </asset>
    
    <!-- Define joint and actuator defaults -->
    <default>
        <default class="ur10e">
            <joint axis="0 1 0" range="-6.28319 6.28319" armature="0.1"/>
            <position ctrlrange="-6.2831 6.2831"/>
            <default class="size4">
                <joint damping="10"/>
            </default>
            <default class="size3">
                <joint damping="5"/>
                <default class="size3_limited">
                    <joint range="-3.1415 3.1415"/>
                </default>
            </default>
            <default class="size2">
                <joint damping="2"/>
            </default>
            <default class="visual">
                <geom type="mesh" contype="0" conaffinity="0" group="2"/>
            </default>
            <default class="collision">
                <geom type="capsule" group="3"/>
                <default class="eef_collision">
                    <geom type="cylinder"/>
                </default>
            </default>
            <site size="0.001" rgba="0.5 0.5 0.5 0.3" group="4"/>
        </default>
    </default>
    
    <worldbody>
        <!-- Lighting -->
        <light directional="true" diffuse=".8 .8 .8" specular=".2 .2 .2" pos="0 0 5" dir="0 0 -1"/>
        <light directional="true" diffuse=".8 .8 .8" specular=".2 .2 .2" pos="0 0 4" dir="0 0 -1" castshadow="false"/>
        
        <!-- Ground plane -->
        <geom name="ground" type="plane" size="5 5 0.1" material="matplane"/>
        
        <!-- Wall (YZ plane, facing X direction) -->
        <geom name="wall" type="box" pos="1.2 0 1.5" size="0.01 3.0 1.5" material="wall"/>
        
        <!-- Flat Mounted UR10 Robot (parallel to floor, perpendicular to wall) -->
        <body name="flat_base_block" pos="0.2 0 0.8">
            <geom name="flat_block" type="box" size="0.2 0.2 0.8" material="flatmount"/>
            
            <!-- Flat mounted UR10 robot -->
            <body name="flat_robot_base" pos="0 0 0.8" childclass="ur10e">
                <geom mesh="base_0" material="black" class="visual"/>
                <geom mesh="base_1" material="jointgray" class="visual"/>
                <body name="flat_shoulder_link" pos="0 0 0.181">
                    <inertial pos="0 0 0" mass="7.778" diaginertia="0.0314743 0.0314743 0.0218756"/>
                    <joint name="flat_shoulder_pan_joint" class="size4" axis="0 0 1"/>
                    <geom mesh="shoulder_0" material="urblue" class="visual"/>
                    <geom mesh="shoulder_1" material="black" class="visual"/>
                    <geom mesh="shoulder_2" material="jointgray" class="visual"/>
                    <geom class="collision" size="0.078 0.08" pos="0 0 -0.05"/>
                    <body name="flat_upper_arm_link" pos="0 0.176 0" quat="1 0 1 0">
                        <inertial pos="0 0 0.3065" mass="12.93" diaginertia="0.423074 0.423074 0.0363656"/>
                        <joint name="flat_shoulder_lift_joint" class="size4"/>
                        <geom mesh="upperarm_0" material="black" class="visual"/>
                        <geom mesh="upperarm_1" material="jointgray" class="visual"/>
                        <geom mesh="upperarm_2" material="urblue" class="visual"/>
                        <geom mesh="upperarm_3" material="linkgray" class="visual"/>
                        <geom class="collision" pos="0 -0.05 0" quat="1 1 0 0" size="0.078 0.08"/>
                        <geom class="collision" size="0.06 0.3" pos="0 0 0.3"/>
                        <body name="flat_forearm_link" pos="0 -0.137 0.613">
                            <inertial pos="0 0 0.2855" mass="3.87" diaginertia="0.11059 0.11059 0.0108844"/>
                            <joint name="flat_elbow_joint" class="size3_limited"/>
                            <geom mesh="forearm_0" material="urblue" class="visual"/>
                            <geom mesh="forearm_1" material="black" class="visual"/>
                            <geom mesh="forearm_2" material="jointgray" class="visual"/>
                            <geom mesh="forearm_3" material="linkgray" class="visual"/>
                            <geom class="collision" pos="0 0.08 0" quat="1 1 0 0" size="0.058 0.065"/>
                            <geom class="collision" size="0.043 0.28" pos="0 0 0.29"/>
                            <body name="flat_wrist_1_link" pos="0 0 0.571" quat="1 0 1 0">
                                <inertial pos="0 0.135 0" quat="0.5 0.5 -0.5 0.5" mass="1.96" diaginertia="0.0055125 0.00510825 0.00510825"/>
                                <joint name="flat_wrist_1_joint" class="size2"/>
                                <geom mesh="wrist1_0" material="black" class="visual"/>
                                <geom mesh="wrist1_1" material="urblue" class="visual"/>
                                <geom mesh="wrist1_2" material="jointgray" class="visual"/>
                                <geom class="collision" pos="0 0.06 0" quat="1 1 0 0" size="0.05 0.07"/>
                                <body name="flat_wrist_2_link" pos="0 0.135 0">
                                    <inertial pos="0 0 0.12" quat="0.5 0.5 -0.5 0.5" mass="1.96" diaginertia="0.0055125 0.00510825 0.00510825"/>
                                    <joint name="flat_wrist_2_joint" axis="0 0 1" class="size2"/>
                                    <geom mesh="wrist2_0" material="black" class="visual"/>
                                    <geom mesh="wrist2_1" material="urblue" class="visual"/>
                                    <geom mesh="wrist2_2" material="jointgray" class="visual"/>
                                    <geom class="collision" size="0.046 0.065" pos="0 0 0.05"/>
                                    <geom class="collision" pos="0 0.028 0.12" quat="1 1 0 0" size="0.046 0.043"/>
                                    <body name="flat_wrist_3_link" pos="0 0 0.12">
                                        <inertial pos="0 0.092 0" quat="0 1 -1 0" mass="0.202" diaginertia="0.000204525 0.000144346 0.000144346"/>
                                        <joint name="flat_wrist_3_joint" class="size2"/>
                                        <geom material="linkgray" mesh="wrist3" class="visual"/>
                                        <geom class="eef_collision" pos="0 0.097 0" quat="1 1 0 0" size="0.046 0.02"/>
                                        <site name="flat_ee" pos="0 0.12 0" rgba="1 0 0 0.5" size="0.01"/>
                                        
                                        <!-- Drywall finishing tool attachment for flat robot -->
                                        <body name="flat_tool" pos="0 0.12 0">
                                            <geom name="flat_tool_geom" type="cylinder" size="0.03 0.0525" rgba="0.3 0.3 0.8 1" quat="0 0 0.7071068 0.7071068"/>
                                            <site name="flat_tool_tip" pos="0 0.0525 0" rgba="1 0 0 1" size="0.005"/>
                                        </body>
                                    </body>
                                </body>
                            </body>
                        </body>
                    </body>
                </body>
            </body>
        </body>
        
        <!-- Perpendicular Mounted UR10 Robot (perpendicular to floor, parallel to wall) -->
        <body name="perp_base_block" pos="0.2 0 0.8">
            <geom name="perp_block" type="box" size="0.2 0.2 0.8" material="perpmount"/>
            
            <!-- Perpendicular mounted UR10 robot (rotated 90 degrees around Y) -->
            <body name="perp_robot_base" pos="0 0 0.8" quat="0.7071068 0 0.7071068 0" childclass="ur10e">
                <geom mesh="base_0" material="black" class="visual"/>
                <geom mesh="base_1" material="jointgray" class="visual"/>
                <body name="perp_shoulder_link" pos="0 0 0.181">
                    <inertial pos="0 0 0" mass="7.778" diaginertia="0.0314743 0.0314743 0.0218756"/>
                    <joint name="perp_shoulder_pan_joint" class="size4" axis="0 0 1"/>
                    <geom mesh="shoulder_0" material="urblue" class="visual"/>
                    <geom mesh="shoulder_1" material="black" class="visual"/>
                    <geom mesh="shoulder_2" material="jointgray" class="visual"/>
                    <geom class="collision" size="0.078 0.08" pos="0 0 -0.05"/>
                    <body name="perp_upper_arm_link" pos="0 0.176 0" quat="1 0 1 0">
                        <inertial pos="0 0 0.3065" mass="12.93" diaginertia="0.423074 0.423074 0.0363656"/>
                        <joint name="perp_shoulder_lift_joint" class="size4"/>
                        <geom mesh="upperarm_0" material="black" class="visual"/>
                        <geom mesh="upperarm_1" material="jointgray" class="visual"/>
                        <geom mesh="upperarm_2" material="urblue" class="visual"/>
                        <geom mesh="upperarm_3" material="linkgray" class="visual"/>
                        <geom class="collision" pos="0 -0.05 0" quat="1 1 0 0" size="0.078 0.08"/>
                        <geom class="collision" size="0.06 0.3" pos="0 0 0.3"/>
                        <body name="perp_forearm_link" pos="0 -0.137 0.613">
                            <inertial pos="0 0 0.2855" mass="3.87" diaginertia="0.11059 0.11059 0.0108844"/>
                            <joint name="perp_elbow_joint" class="size3_limited"/>
                            <geom mesh="forearm_0" material="urblue" class="visual"/>
                            <geom mesh="forearm_1" material="black" class="visual"/>
                            <geom mesh="forearm_2" material="jointgray" class="visual"/>
                            <geom mesh="forearm_3" material="linkgray" class="visual"/>
                            <geom class="collision" pos="0 0.08 0" quat="1 1 0 0" size="0.058 0.065"/>
                            <geom class="collision" size="0.043 0.28" pos="0 0 0.29"/>
                            <body name="perp_wrist_1_link" pos="0 0 0.571" quat="1 0 1 0">
                                <inertial pos="0 0.135 0" quat="0.5 0.5 -0.5 0.5" mass="1.96" diaginertia="0.0055125 0.00510825 0.00510825"/>
                                <joint name="perp_wrist_1_joint" class="size2"/>
                                <geom mesh="wrist1_0" material="black" class="visual"/>
                                <geom mesh="wrist1_1" material="urblue" class="visual"/>
                                <geom mesh="wrist1_2" material="jointgray" class="visual"/>
                                <geom class="collision" pos="0 0.06 0" quat="1 1 0 0" size="0.05 0.07"/>
                                <body name="perp_wrist_2_link" pos="0 0.135 0">
                                    <inertial pos="0 0 0.12" quat="0.5 0.5 -0.5 0.5" mass="1.96" diaginertia="0.0055125 0.00510825 0.00510825"/>
                                    <joint name="perp_wrist_2_joint" axis="0 0 1" class="size2"/>
                                    <geom mesh="wrist2_0" material="black" class="visual"/>
                                    <geom mesh="wrist2_1" material="urblue" class="visual"/>
                                    <geom mesh="wrist2_2" material="jointgray" class="visual"/>
                                    <geom class="collision" size="0.046 0.065" pos="0 0 0.05"/>
                                    <geom class="collision" pos="0 0.028 0.12" quat="1 1 0 0" size="0.046 0.043"/>
                                    <body name="perp_wrist_3_link" pos="0 0 0.12">
                                        <inertial pos="0 0.092 0" quat="0 1 -1 0" mass="0.202" diaginertia="0.000204525 0.000144346 0.000144346"/>
                                        <joint name="perp_wrist_3_joint" class="size2"/>
                                        <geom material="linkgray" mesh="wrist3" class="visual"/>
                                        <geom class="eef_collision" pos="0 0.097 0" quat="1 1 0 0" size="0.046 0.02"/>
                                        <site name="perp_ee" pos="0 0.12 0" rgba="0 0 1 0.5" size="0.01"/>
                                        
                                        <!-- Drywall finishing tool attachment for perpendicular robot -->
                                        <body name="perp_tool" pos="0 0.12 0">
                                            <geom name="perp_tool_geom" type="cylinder" size="0.03 0.0525" rgba="0.3 0.3 0.8 1" quat="0 0 0.7071068 0.7071068"/>
                                            <site name="perp_tool_tip" pos="0 0.0525 0" rgba="0 0 1 1" size="0.005"/>
                                        </body>
                                    </body>
                                </body>
                            </body>
                        </body>
                    </body>
                </body>
            </body>
        </body>
        
        <!-- Visualization markers for reachable points -->
        <site name="flat_reach_point" group="3" pos="1.0 0 1.0" size="0.01" rgba="1 0 0 0.5" type="sphere"/>
        <site name="perp_reach_point" group="3" pos="1.0 0 1.0" size="0.01" rgba="0 0 1 0.5" type="sphere"/>
    </worldbody>
    
    <actuator>
        <!-- Flat robot actuators -->
        <position name="flat_shoulder_pan" joint="flat_shoulder_pan_joint" ctrlrange="-6.2831 6.2831"/>
        <position name="flat_shoulder_lift" joint="flat_shoulder_lift_joint" ctrlrange="-6.2831 6.2831"/>
        <position name="flat_elbow" joint="flat_elbow_joint" ctrlrange="-3.1415 3.1415"/>
        <position name="flat_wrist_1" joint="flat_wrist_1_joint" ctrlrange="-6.2831 6.2831"/>
        <position name="flat_wrist_2" joint="flat_wrist_2_joint" ctrlrange="-6.2831 6.2831"/>
        <position name="flat_wrist_3" joint="flat_wrist_3_joint" ctrlrange="-6.2831 6.2831"/>
        
        <!-- Perpendicular robot actuators -->
        <position name="perp_shoulder_pan" joint="perp_shoulder_pan_joint" ctrlrange="-6.2831 6.2831"/>
        <position name="perp_shoulder_lift" joint="perp_shoulder_lift_joint" ctrlrange="-6.2831 6.2831"/>
        <position name="perp_elbow" joint="perp_elbow_joint" ctrlrange="-3.1415 3.1415"/>
        <position name="perp_wrist_1" joint="perp_wrist_1_joint" ctrlrange="-6.2831 6.2831"/>
        <position name="perp_wrist_2" joint="perp_wrist_2_joint" ctrlrange="-6.2831 6.2831"/>
        <position name="perp_wrist_3" joint="perp_wrist_3_joint" ctrlrange="-6.2831 6.2831"/>
    </actuator>
</mujoco> 